<?xml version="1.0"?>
<robot name="cleaning_robot">

  <link name="base_footprint"/>

  <joint name="base_footprint_joint" type="fixed">
    <parent link="base_footprint"/>
    <child link="base_link"/>
    <origin xyz="0 0 0" rpy="0 0 0"/>
  </joint>

  <link name="base_link">
    <visual>
      <geometry>
        <cylinder length="0.1" radius="0.2"/>
      </geometry>
      <material name="blue">
        <color rgba="0 0 1 1"/>
      </material>
    </visual>
    <collision>
      <geometry>
        <cylinder length="0.1" radius="0.2"/>
      </geometry>
    </collision>
    <inertial>
      <mass value="5.0"/>
      <inertia ixx="0.1" iyy="0.1" izz="0.1" ixy="0" ixz="0" iyz="0"/>
    </inertial>
  </link>

  <link name="left_wheel">
    <visual>
      <geometry><cylinder length="0.05" radius="0.05"/></geometry>
      <material name="black"><color rgba="0 0 0 1"/></material>
    </visual>
    <collision>
      <geometry><cylinder length="0.05" radius="0.05"/></geometry>
    </collision>
    <inertial>
      <mass value="0.5"/>
      <inertia ixx="0.01" iyy="0.01" izz="0.01" ixy="0" ixz="0" iyz="0"/>
    </inertial>
  </link>

  <link name="right_wheel">
    <visual>
      <geometry><cylinder length="0.05" radius="0.05"/></geometry>
      <material name="black"><color rgba="0 0 0 1"/></material>
    </visual>
    <collision>
      <geometry><cylinder length="0.05" radius="0.05"/></geometry>
    </collision>
    <inertial>
      <mass value="0.5"/>
      <inertia ixx="0.01" iyy="0.01" izz="0.01" ixy="0" ixz="0" iyz="0"/>
    </inertial>
  </link>

  <link name="lidar_link">
    <visual>
      <geometry><cylinder length="0.05" radius="0.05"/></geometry>
      <material name="red"><color rgba="1 0 0 1"/></material>
    </visual>
  </link>

  <joint name="left_wheel_joint" type="continuous">
    <parent link="base_link"/>
    <child link="left_wheel"/>
    <origin xyz="0 0.15 -0.05" rpy="-1.5707 0 0"/>
    <axis xyz="0 0 1"/>
  </joint>

  <joint name="right_wheel_joint" type="continuous">
    <parent link="base_link"/>
    <child link="right_wheel"/>
    <origin xyz="0 -0.15 -0.05" rpy="-1.5707 0 0"/>
    <axis xyz="0 0 1"/>
  </joint>

  <joint name="lidar_joint" type="fixed">
    <parent link="base_link"/>
    <child link="lidar_link"/>
    <origin xyz="0 0 0.1" rpy="0 0 0"/>
  </joint>

  <!-- Differential Drive Plugin -->
  <gazebo>
    <plugin filename="gz-sim-diff-drive-system"
            name="gz::sim::systems::DiffDrive">
      <left_joint>left_wheel_joint</left_joint>
      <right_joint>right_wheel_joint</right_joint>
      <wheel_separation>0.3</wheel_separation>
      <wheel_radius>0.05</wheel_radius>
      <topic>/cmd_vel</topic>
      <odom_topic>/odom</odom_topic>
      <frame_id>odom</frame_id>
      <child_frame_id>base_link</child_frame_id>
      <max_linear_acceleration>2</max_linear_acceleration>
    </plugin>
  </gazebo>

  <!-- LiDAR Plugin -->
  <gazebo reference="lidar_link">
    <sensor name="lidar" type="gpu_lidar">
      <update_rate>10</update_rate>
      <topic>/scan</topic>
      <gz_frame_id>lidar_link</gz_frame_id>
      <lidar>
        <scan>
          <horizontal>
            <samples>360</samples>
            <resolution>1</resolution>
            <min_angle>-3.14159</min_angle>
            <max_angle>3.14159</max_angle>
          </horizontal>
        </scan>
        <range>
          <min>0.1</min>
          <max>10.0</max>
        </range>
      </lidar>
      <always_on>true</always_on>
      <visualize>true</visualize>
    </sensor>
  </gazebo>

</robot>
